<?xml version="1.0" encoding="UTF-8"?>
<!-- Generated by org.testng.reporters.JUnitReportReporter -->
<testsuite skipped="0" hostname="DESKTOP-78D4HDH" name="basicsTestNG.TestNGExpectedExceptions" tests="1" failures="0" timestamp="05 Oct 2018 01:48:24 GMT" time="3.022" errors="1">
  <testcase name="testA2" time="3.022" classname="basicsTestNG.TestNGExpectedExceptions">
    <error type="org.testng.TestException" message="
The exception was thrown with the wrong message: expected &quot;.*time-out*.&quot; but got &quot;Method basicsTestNG.TestNGExpectedExceptions.testA2() didn&#039;t finish within the time-out 3000&quot;">
      <![CDATA[org.testng.TestException: 
The exception was thrown with the wrong message: expected ".*time-out*." but got "Method basicsTestNG.TestNGExpectedExceptions.testA2() didn't finish within the time-out 3000"
at org.testng.internal.ExpectedExceptionsHolder.wrongException(ExpectedExceptionsHolder.java:71)
at org.testng.internal.Invoker.considerExceptions(Invoker.java:1129)
at org.testng.internal.Invoker.invokeMethod(Invoker.java:612)
at org.testng.internal.Invoker.invokeTestMethod(Invoker.java:716)
at org.testng.internal.Invoker.invokeTestMethods(Invoker.java:988)
at org.testng.internal.TestMethodWorker.invokeTestMethods(TestMethodWorker.java:125)
at org.testng.internal.TestMethodWorker.run(TestMethodWorker.java:109)
at org.testng.TestRunner.privateRun(TestRunner.java:648)
at org.testng.TestRunner.run(TestRunner.java:505)
at org.testng.SuiteRunner.runTest(SuiteRunner.java:455)
at org.testng.SuiteRunner.runSequentially(SuiteRunner.java:450)
at org.testng.SuiteRunner.privateRun(SuiteRunner.java:415)
at org.testng.SuiteRunner.run(SuiteRunner.java:364)
at org.testng.SuiteRunnerWorker.runSuite(SuiteRunnerWorker.java:52)
at org.testng.SuiteRunnerWorker.run(SuiteRunnerWorker.java:84)
at org.testng.TestNG.runSuitesSequentially(TestNG.java:1208)
at org.testng.TestNG.runSuitesLocally(TestNG.java:1137)
at org.testng.TestNG.runSuites(TestNG.java:1049)
at org.testng.TestNG.run(TestNG.java:1017)
at org.testng.remote.AbstractRemoteTestNG.run(AbstractRemoteTestNG.java:114)
at org.testng.remote.RemoteTestNG.initAndRun(RemoteTestNG.java:251)
at org.testng.remote.RemoteTestNG.main(RemoteTestNG.java:77)
Caused by: org.testng.internal.thread.ThreadTimeoutException: Method basicsTestNG.TestNGExpectedExceptions.testA2() didn't finish within the time-out 3000
at java.util.concurrent.FutureTask.setException(FutureTask.java:250)
at java.util.concurrent.FutureTask.run(FutureTask.java:271)
at java.util.concurrent.ThreadPoolExecutor.runWorker(ThreadPoolExecutor.java:1149)
at java.util.concurrent.ThreadPoolExecutor$Worker.run(ThreadPoolExecutor.java:624)
at java.lang.Thread.run(Thread.java:748)
]]>
    </error>
  </testcase> <!-- testA2 -->
</testsuite> <!-- basicsTestNG.TestNGExpectedExceptions -->
